Workbook

Sheet วิธีใช้
A1: 📘 วิธีใช้แดชบอร์ด Termthukshop
A3: ยินดีต้อนรับสู่ระบบจัดการร้านเติมเกม Termthukshop
A5: 🎯 โครงสร้างชีท
A7: 1. ภาพรวม — Dashboard สรุป KPI / กราฟเกมขายดี / สรุปสต๊อก / Supply
A8: 2. ประวัติการขาย — บันทึกรายการขายทั้งหมด (มี Dropdown และสูตรคำนวณกำไรอัตโนมัติ)
A9: 3. สต๊อก-iTunes / สต๊อก-Razer / สต๊อก-Mycard / สต๊อก-USDT-PHP — บันทึกสต๊อกแยกประเภท พร้อมราคาเฉลี่ย
A10: 4. Supply — บันทึก Supply จากผู้ขาย 4 ราย (จอนชาวไร่ / Kingpro / Over / 24BuyM)
A11: 5. วิเคราะห์ SKU — Top 20 เกม + บทวิเคราะห์อัตโนมัติ
A12: 6. รายชื่อเกม — สรุปต่อเกม + เครื่องมือคำนวนราคา
A14: 🧭 วิธีใช้
A16: • เริ่มจากชีท "ประวัติการขาย" — กรอกข้อมูลทีละแถว เลือกสต๊อกและช่องทางจาก Dropdown
A17: • คอลัมน์ที่เป็นสีน้ำเงิน = ช่องที่ผู้ใช้กรอกเอง / สีดำ = สูตรคำนวณ (อย่าแก้)
... A26: • ตรวจสอบ Margin เฉลี่ย — ถ้าต่ำกว่า 10% ให้พิจารณาปรับราคาขายหรือต่อรองต้นทุน

Sheet ภาพรวม
A1: 🎮 Termthukshop — Dashboard ภาพรวม
B3: ต้นทุนรวม | D3: ยอดขายรวม | F3: กำไรรวม | H3: จำนวนรายการ
B4: =SUM(ประวัติการขาย!G4:G203) -> 2075 | D4: =SUM(ประวัติการขาย!H4:H203) -> 2555 | F4: =D4-B4 -> 480 | H4: =COUNTA(ประวัติการขาย!A4:A203) -> 10
B6: Margin เฉลี่ย | D6: =IFERROR(F4/D4,0) -> 0.18786693 | F6: ราคาขายเฉลี่ย/รายการ | H6: =IFERROR(D4/H4,0) -> 255.5
B8: 🏆 เกมขายดี (Top 10 ตามจำนวนรายการ)
A9: อันดับ | B9: เกม | C9: จำนวน | D9: ยอดขาย | E9: ต้นทุน | F9: กำไร | G9: Margin %
B10: 1 | C10: =IFERROR(IF(LARGE(_agg!$G$2:$G$60,1)>=1,INDEX(_agg!$A$2:$A$60,MATCH(LARGE(_agg!$G$2:$G$60,1),_agg!$G$2:$G$60,0)),""),"") -> Genshin Impact | D10: =IF(C10="","",IFERROR(VLOOKUP(C10,_agg!$A$2:$F$60,2,FALSE()),"")) -> 3 | E10: =IF(C10="","",IFERROR(VLOOKUP(C10,_agg!$A$2:$F$60,3,FALSE()),"")) -> 1520 | F10: =IF(C10="","",IFERROR(VLOOKUP(C10,_agg!$A$2:$F$60,4,FALSE()),"")) -> 1280 | G10: =IF(C10="","",IFERROR(VLOOKUP(C10,_agg!$A$2:$F$60,5,FALSE()),"")) -> 240 | H10: =IF(C10="","",IFERROR(VLOOKUP(C10,_agg!$A$2:$F$60,6,FALSE()),"")) -> 0.15789474
B11: 2 | C11: =IFERROR(IF(LARGE(_agg!$G$2:$G$60,2)>=1,INDEX(_agg!$A$2:$A$60,MATCH(LARGE(_agg!$G$2:$G$60,2),_agg!$G$2:$G$60,0)),""),"") -> Free Fire | D11: =IF(C11="","",IFERROR(VLOOKUP(C11,_agg!$A$2:$F$60,2,FALSE()),"")) -> 3 | E11: =IF(C11="","",IFERROR(VLOOKUP(C11,_agg!$A$2:$F$60,3,FALSE()),"")) -> 290 | F11: =IF(C11="","",IFERROR(VLOOKUP(C11,_agg!$A$2:$F$60,4,FALSE()),"")) -> 215 | G11: =IF(C11="","",IFERROR(VLOOKUP(C11,_agg!$A$2:$F$60,5,FALSE()),"")) -> 75 | H11: =IF(C11="","",IFERROR(VLOOKUP(C11,_agg!$A$2:$F$60,6,FALSE()),"")) -> 0.25862069
B12: 3 | C12: =IFERROR(IF(LARGE(_agg!$G$2:$G$60,3)>=1,INDEX(_agg!$A$2:$A$60,MATCH(LARGE(_agg!$G$2:$G$60,3),_agg!$G$2:$G$60,0)),""),"") -> ROV | D12: =IF(C12="","",IFERROR(VLOOKUP(C12,_agg!$A$2:$F$60,2,FALSE()),"")) -> 2 | E12: =IF(C12="","",IFERROR(VLOOKUP(C12,_agg!$A$2:$F$60,3,FALSE()),"")) -> 255 | F12: =IF(C12="","",IFERROR(VLOOKUP(C12,_agg!$A$2:$F$60,4,FALSE()),"")) -> 190 | G12: =IF(C12="","",IFERROR(VLOOKUP(C12,_agg!$A$2:$F$60,5,FALSE()),"")) -> 65 | H12: =IF(C12="","",IFERROR(VLOOKUP(C12,_agg!$A$2:$F$60,6,FALSE()),"")) -> 0.25490196
B13: 4 | C13: =IFERROR(IF(LARGE(_agg!$G$2:$G$60,4)>=1,INDEX(_agg!$A$2:$A$60,MATCH(LARGE(_agg!$G$2:$G$60,4),_agg!$G$2:$G$60,0)),""),"") -> PUBG Mobile | D13: =IF(C13="","",IFERROR(VLOOKUP(C13,_agg!$A$2:$F$60,2,FALSE()),"")) -> 1 | E13: =IF(C13="","",IFERROR(VLOOKUP(C13,_agg!$A$2:$F$60,3,FALSE()),"")) -> 260 | F13: =IF(C13="","",IFERROR(VLOOKUP(C13,_agg!$A$2:$F$60,4,FALSE()),"")) -> 210 | G13: =IF(C13="","",IFERROR(VLOOKUP(C13,_agg!$A$2:$F$60,5,FALSE()),"")) -> 50 | H13: =IF(C13="","",IFERROR(VLOOKUP(C13,_agg!$A$2:$F$60,6,FALSE()),"")) -> 0.19230769
B14: 5 | C14: =IFERROR(IF(LARGE(_agg!$G$2:$G$60,5)>=1,INDEX(_agg!$A$2:$A$60,MATCH(LARGE(_agg!$G$2:$G$60,5),_agg!$G$2:$G$60,0)),""),"") -> Mobile Legends | D14: =IF(C14="","",IFERROR(VLOOKUP(C14,_agg!$A$2:$F$60,2,FALSE()),"")) -> 1 | E14: =IF(C14="","",IFERROR(VLOOKUP(C14,_agg!$A$2:$F$60,3,FALSE()),"")) -> 230 | F14: =IF(C14="","",IFERROR(VLOOKUP(C14,_agg!$A$2:$F$60,4,FALSE()),"")) -> 180 | G14: =IF(C14="","",IFERROR(VLOOKUP(C14,_agg!$A$2:$F$60,5,FALSE()),"")) -> 50 | H14: =IF(C14="","",IFERROR(VLOOKUP(C14,_agg!$A$2:$F$60,6,FALSE()),"")) -> 0.2173913
B15: 6 | C15: =IFERROR(IF(LARGE(_agg!$G$2:$G$60,6)>=1,INDEX(_agg!$A$2:$A$60,MATCH(LARGE(_agg!$G$2:$G$60,6),_agg!$G$2:$G$60,0)),""),"") | D15: =IF(C15="","",IFERROR(VLOOKUP(C15,_agg!$A$2:$F$60,2,FALSE()),"")) | E15: =IF(C15="","",IFERROR(VLOOKUP(C15,_agg!$A$2:$F$60,3,FALSE()),"")) | F15: =IF(C15="","",IFERROR(VLOOKUP(C15,_agg!$A$2:$F$60,4,FALSE()),"")) | G15: =IF(C15="","",IFERROR(VLOOKUP(C15,_agg!$A$2:$F$60,5,FALSE()),"")) | H15: =IF(C15="","",IFERROR(VLOOKUP(C15,_agg!$A$2:$F$60,6,FALSE()),""))
B16: 7 | C16: =IFERROR(IF(LARGE(_agg!$G$2:$G$60,7)>=1,INDEX(_agg!$A$2:$A$60,MATCH(LARGE(_agg!$G$2:$G$60,7),_agg!$G$2:$G$60,0)),""),"") | D16: =IF(C16="","",IFERROR(VLOOKUP(C16,_agg!$A$2:$F$60,2,FALSE()),"")) | E16: =IF(C16="","",IFERROR(VLOOKUP(C16,_agg!$A$2:$F$60,3,FALSE()),"")) | F16: =IF(C16="","",IFERROR(VLOOKUP(C16,_agg!$A$2:$F$60,4,FALSE()),"")) | G16: =IF(C16="","",IFERROR(VLOOKUP(C16,_agg!$A$2:$F$60,5,FALSE()),"")) | H16: =IF(C16="","",IFERROR(VLOOKUP(C16,_agg!$A$2:$F$60,6,FALSE()),""))
B17: 8 | C17: =IFERROR(IF(LARGE(_agg!$G$2:$G$60,8)>=1,INDEX(_agg!$A$2:$A$60,MATCH(LARGE(_agg!$G$2:$G$60,8),_agg!$G$2:$G$60,0)),""),"") | D17: =IF(C17="","",IFERROR(VLOOKUP(C17,_agg!$A$2:$F$60,2,FALSE()),"")) | E17: =IF(C17="","",IFERROR(VLOOKUP(C17,_agg!$A$2:$F$60,3,FALSE()),"")) | F17: =IF(C17="","",IFERROR(VLOOKUP(C17,_agg!$A$2:$F$60,4,FALSE()),"")) | G17: =IF(C17="","",IFERROR(VLOOKUP(C17,_agg!$A$2:$F$60,5,FALSE()),"")) | H17: =IF(C17="","",IFERROR(VLOOKUP(C17,_agg!$A$2:$F$60,6,FALSE()),""))
B18: 9 | C18: =IFERROR(IF(LARGE(_agg!$G$2:$G$60,9)>=1,INDEX(_agg!$A$2:$A$60,MATCH(LARGE(_agg!$G$2:$G$60,9),_agg!$G$2:$G$60,0)),""),"") | D18: =IF(C18="","",IFERROR(VLOOKUP(C18,_agg!$A$2:$F$60,2,FALSE()),"")) | E18: =IF(C18="","",IFERROR(VLOOKUP(C18,_agg!$A$2:$F$60,3,FALSE()),"")) | F18: =IF(C18="","",IFERROR(VLOOKUP(C18,_agg!$A$2:$F$60,4,FALSE()),"")) | G18: =IF(C18="","",IFERROR(VLOOKUP(C18,_agg!$A$2:$F$60,5,FALSE()),"")) | H18: =IF(C18="","",IFERROR(VLOOKUP(C18,_agg!$A$2:$F$60,6,FALSE()),""))
B19: 10 | C19: =IFERROR(IF(LARGE(_agg!$G$2:$G$60,10)>=1,INDEX(_agg!$A$2:$A$60,MATCH(LARGE(_agg!$G$2:$G$60,10),_agg!$G$2:$G$60,0)),""),"") | D19: =IF(C19="","",IFERROR(VLOOKUP(C19,_agg!$A$2:$F$60,2,FALSE()),"")) | E19: =IF(C19="","",IFERROR(VLOOKUP(C19,_agg!$A$2:$F$60,3,FALSE()),"")) | F19: =IF(C19="","",IFERROR(VLOOKUP(C19,_agg!$A$2:$F$60,4,FALSE()),"")) | G19: =IF(C19="","",IFERROR(VLOOKUP(C19,_agg!$A$2:$F$60,5,FALSE()),"")) | H19: =IF(C19="","",IFERROR(VLOOKUP(C19,_agg!$A$2:$F$60,6,FALSE()),""))
B22: 📦 สรุปสต๊อก / Rate (ราคาเฉลี่ย/หน่วย)
A23: สต๊อก | B23: มูลค่า/จำนวนรวม | C23: ต้นทุนรวม (฿) | D23: ราคาเฉลี่ย/หน่วย
B24: iTunes | C24: =SUM('สต๊อก-iTunes'!C4:C200) -> 99.8 | D24: =SUM('สต๊อก-iTunes'!D4:D200) -> 8280 | E24: =IFERROR(D24/C24,0) -> 82.965932
B25: Razer | C25: =SUM('สต๊อก-Razer'!C4:C200) -> 68.3 | D25: =SUM('สต๊อก-Razer'!D4:D200) -> 5105 | E25: =IFERROR(D25/C25,0) -> 74.743777
B26: Mycard | C26: =SUM('สต๊อก-Mycard'!C4:C200) -> 0 | D26: =SUM('สต๊อก-Mycard'!D4:D200) -> 0 | E26: =IFERROR(D26/C26,0) -> 0
B27: USDT/PHP | C27: =SUM('สต๊อก-USDT-PHP'!C4:C200) -> 36.82 | D27: =SUM('สต๊อก-USDT-PHP'!D4:D200) -> 3744 | E27: =IFERROR(D27/C27,0) -> 101.68387
B30: 🚚 Supply (ต้นทุนรวมจากผู้ขาย)
A31: ผู้ขาย | B31: จำนวนรายการ | C31: ต้นทุนรวม (฿) | D31: ค้างส่ง
B32: จอนชาวไร่ | C32: =COUNTIF(Supply!B4:B200,"จอนชาวไร่") -> 1 | D32: =SUMIF(Supply!B4:B200,"จอนชาวไร่",Supply!E4:E200) -> 3280 | E32: =COUNTIFS(Supply!B4:B200,"จอนชาวไร่",Supply!F4:F200,"<>ได้รับแล้ว",Supply!F4:F200,"<>") -> 0
B33: Kingpro | C33: =COUNTIF(Supply!B4:B200,"Kingpro") -> 2 | D33: =SUMIF(Supply!B4:B200,"Kingpro",Supply!E4:E200) -> 5025 | E33: =COUNTIFS(Supply!B4:B200,"Kingpro",Supply!F4:F200,"<>ได้รับแล้ว",Supply!F4:F200,"<>") -> 0
B34: Over | C34: =COUNTIF(Supply!B4:B200,"Over") -> 2 | D34: =SUMIF(Supply!B4:B200,"Over",Supply!E4:E200) -> 7000 | E34: =COUNTIFS(Supply!B4:B200,"Over",Supply!F4:F200,"<>ได้รับแล้ว",Supply!F4:F200,"<>") -> 1
B35: 24BuyM | C35: =COUNTIF(Supply!B4:B200,"24BuyM") -> 2 | D35: =SUMIF(Supply!B4:B200,"24BuyM",Supply!E4:E200) -> 1824 | E35: =COUNTIFS(Supply!B4:B200,"24BuyM",Supply!F4:F200,"<>ได้รับแล้ว",Supply!F4:F200,"<>") -> 1

Sheet ประวัติการขาย
A1: 📜 ประวัติการขาย — Termthukshop
A3: วันที่ | B3: ผู้ซื้อ | C3: ผู้ขาย | D3: เกม | E3: ช่องทาง | F3: สต๊อก | G3: ต้นทุน (฿) | H3: ยอดขาย (฿) | I3: กำไร (฿) | J3: Margin % | K3: หมายเหตุ
A4: 2026-04-25 | B4: ลูกค้า A | C4: แอดมิน | D4: Free Fire | E4: TrueWallet | F4: iTunes | G4: 85 | H4: 110 | I4: =IFERROR(H4-G4,0) -> 25 | J4: =IFERROR((H4-G4)/H4,0) -> 0.22727273 | K4: Voucher 100
A5: 2026-04-26 | B5: ลูกค้า B | C5: แอดมิน | D5: ROV | E5: SCB | F5: Razer | G5: 95 | H5: 130 | I5: =IFERROR(H5-G5,0) -> 35 | J5: =IFERROR((H5-G5)/H5,0) -> 0.26923077 | K5: เพชร 80
A6: 2026-04-26 | B6: ลูกค้า C | C6: แอดมิน | D6: Genshin Impact | E6: USDT | F6: USDT/PHP | G6: 320 | H6: 380 | I6: =IFERROR(H6-G6,0) -> 60 | J6: =IFERROR((H6-G6)/H6,0) -> 0.15789474 | K6: Welkin
A7: 2026-04-27 | B7: ลูกค้า D | C7: แอดมิน | D7: Mobile Legends | E7: KBank | F7: Razer | G7: 180 | H7: 230 | I7: =IFERROR(H7-G7,0) -> 50 | J7: =IFERROR((H7-G7)/H7,0) -> 0.2173913
A8: 2026-04-27 | B8: ลูกค้า A | C8: แอดมิน | D8: Free Fire | E8: TrueWallet | F8: iTunes | G8: 85 | H8: 110 | I8: =IFERROR(H8-G8,0) -> 25 | J8: =IFERROR((H8-G8)/H8,0) -> 0.22727273
A9: 2026-04-28 | B9: ลูกค้า E | C9: แอดมิน | D9: PUBG Mobile | E9: BBL | F9: Mycard | G9: 210 | H9: 260 | I9: =IFERROR(H9-G9,0) -> 50 | J9: =IFERROR((H9-G9)/H9,0) -> 0.19230769 | K9: UC 660
A10: 2026-04-28 | B10: ลูกค้า F | C10: แอดมิน | D10: Genshin Impact | E10: USDT | F10: USDT/PHP | G10: 640 | H10: 760 | I10: =IFERROR(H10-G10,0) -> 120 | J10: =IFERROR((H10-G10)/H10,0) -> 0.15789474
A11: 2026-04-29 | B11: ลูกค้า G | C11: แอดมิน | D11: ROV | E11: TrueWallet | F11: Razer | G11: 95 | H11: 125 | I11: =IFERROR(H11-G11,0) -> 30 | J11: =IFERROR((H11-G11)/H11,0) -> 0.24
A12: 2026-04-29 | B12: ลูกค้า H | C12: แอดมิน | D12: Free Fire | E12: PromptPay | F12: iTunes | G12: 45 | H12: 70 | I12: =IFERROR(H12-G12,0) -> 25 | J12: =IFERROR((H12-G12)/H12,0) -> 0.35714286
A13: 2026-04-30 | B13: ลูกค้า A | C13: แอดมิน | D13: Genshin Impact | E13: USDT | F13: USDT/PHP | G13: 320 | H13: 380 | I13: =IFERROR(H13-G13,0) -> 60 | J13: =IFERROR((H13-G13)/H13,0) -> 0.15789474 | K13: ลูกค้าประจำ
I14: =IFERROR(H14-G14,0) -> 0 | J14: =IFERROR((H14-G14)/H14,0) -> 0
I15: =IFERROR(H15-G15,0) -> 0 | J15: =IFERROR((H15-G15)/H15,0) -> 0
I16: =IFERROR(H16-G16,0) -> 0 | J16: =IFERROR((H16-G16)/H16,0) -> 0
I17: =IFERROR(H17-G17,0) -> 0 | J17: =IFERROR((H17-G17)/H17,0) -> 0
I18: =IFERROR(H18-G18,0) -> 0 | J18: =IFERROR((H18-G18)/H18,0) -> 0
I19: =IFERROR(H19-G19,0) -> 0 | J19: =IFERROR((H19-G19)/H19,0) -> 0
I20: =IFERROR(H20-G20,0) -> 0 | J20: =IFERROR((H20-G20)/H20,0) -> 0
I21: =IFERROR(H21-G21,0) -> 0 | J21: =IFERROR((H21-G21)/H21,0) -> 0
I22: =IFERROR(H22-G22,0) -> 0 | J22: =IFERROR((H22-G22)/H22,0) -> 0
I23: =IFERROR(H23-G23,0) -> 0 | J23: =IFERROR((H23-G23)/H23,0) -> 0
I24: =IFERROR(H24-G24,0) -> 0 | J24: =IFERROR((H24-G24)/H24,0) -> 0
I25: =IFERROR(H25-G25,0) -> 0 | J25: =IFERROR((H25-G25)/H25,0) -> 0
... I203: =IFERROR(H203-G203,0) -> 0 | J203: =IFERROR((H203-G203)/H203,0) -> 0

Sheet สต๊อก-iTunes
A1: 📦 สต๊อก-iTunes
A3: วันที่ | B3: มูลค่าหน้าบัตร ($) | C3: ต้นทุน (฿) | D3: ต้นทุนรวม (฿) | E3: ราคา/หน่วย | F3: แหล่งที่ซื้อ | G3: หมายเหตุ | H3: คงเหลือ
A4: 2026-04-20 | B4: 100 | C4: 33 | D4: =IFERROR(B4*C4,0) -> 3300 | E4: =IFERROR(IF(B4=0,0,D4/B4),0) -> 33 | F4: Kingpro | G4: iTunes 100$
A5: 2026-04-22 | B5: 50 | C5: 34 | D5: =IFERROR(B5*C5,0) -> 1700 | E5: =IFERROR(IF(B5=0,0,D5/B5),0) -> 34 | F5: 24BuyM | G5: iTunes 50$
A6: 2026-04-25 | B6: 100 | C6: 32.8 | D6: =IFERROR(B6*C6,0) -> 3280 | E6: =IFERROR(IF(B6=0,0,D6/B6),0) -> 32.8 | F6: จอนชาวไร่
D7: =IFERROR(B7*C7,0) -> 0 | E7: =IFERROR(IF(B7=0,0,D7/B7),0) -> 0
D8: =IFERROR(B8*C8,0) -> 0 | E8: =IFERROR(IF(B8=0,0,D8/B8),0) -> 0
D9: =IFERROR(B9*C9,0) -> 0 | E9: =IFERROR(IF(B9=0,0,D9/B9),0) -> 0
D10: =IFERROR(B10*C10,0) -> 0 | E10: =IFERROR(IF(B10=0,0,D10/B10),0) -> 0
D11: =IFERROR(B11*C11,0) -> 0 | E11: =IFERROR(IF(B11=0,0,D11/B11),0) -> 0
D12: =IFERROR(B12*C12,0) -> 0 | E12: =IFERROR(IF(B12=0,0,D12/B12),0) -> 0
D13: =IFERROR(B13*C13,0) -> 0 | E13: =IFERROR(IF(B13=0,0,D13/B13),0) -> 0
D14: =IFERROR(B14*C14,0) -> 0 | E14: =IFERROR(IF(B14=0,0,D14/B14),0) -> 0
D15: =IFERROR(B15*C15,0) -> 0 | E15: =IFERROR(IF(B15=0,0,D15/B15),0) -> 0
D16: =IFERROR(B16*C16,0) -> 0 | E16: =IFERROR(IF(B16=0,0,D16/B16),0) -> 0
D17: =IFERROR(B17*C17,0) -> 0 | E17: =IFERROR(IF(B17=0,0,D17/B17),0) -> 0
D18: =IFERROR(B18*C18,0) -> 0 | E18: =IFERROR(IF(B18=0,0,D18/B18),0) -> 0
... D203: =IFERROR(B203*C203,0) -> 0 | E203: =IFERROR(IF(B203=0,0,D203/B203),0) -> 0
A205: รวมทั้งหมด | B205: =SUM(B4:B203) -> 250 | D205: =SUM(D4:D203) -> 8280 | E205: =IFERROR(D205/B205,0) -> 33.12

Sheet สต๊อก-Razer
A1: 📦 สต๊อก-Razer
A3: วันที่ | B3: มูลค่าหน้าบัตร ($) | C3: ต้นทุน (฿) | D3: ต้นทุนรวม (฿) | E3: ราคา/หน่วย | F3: แหล่งที่ซื้อ | G3: หมายเหตุ | H3: คงเหลือ
A4: 2026-04-21 | B4: 50 | C4: 34.5 | D4: =IFERROR(B4*C4,0) -> 1725 | E4: =IFERROR(IF(B4=0,0,D4/B4),0) -> 34.5 | F4: Kingpro
A5: 2026-04-25 | B5: 100 | C5: 33.8 | D5: =IFERROR(B5*C5,0) -> 3380 | E5: =IFERROR(IF(B5=0,0,D5/B5),0) -> 33.8 | F5: Over
D6: =IFERROR(B6*C6,0) -> 0 | E6: =IFERROR(IF(B6=0,0,D6/B6),0) -> 0
D7: =IFERROR(B7*C7,0) -> 0 | E7: =IFERROR(IF(B7=0,0,D7/B7),0) -> 0
D8: =IFERROR(B8*C8,0) -> 0 | E8: =IFERROR(IF(B8=0,0,D8/B8),0) -> 0
D9: =IFERROR(B9*C9,0) -> 0 | E9: =IFERROR(IF(B9=0,0,D9/B9),0) -> 0
D10: =IFERROR(B10*C10,0) -> 0 | E10: =IFERROR(IF(B10=0,0,D10/B10),0) -> 0
D11: =IFERROR(B11*C11,0) -> 0 | E11: =IFERROR(IF(B11=0,0,D11/B11),0) -> 0
D12: =IFERROR(B12*C12,0) -> 0 | E12: =IFERROR(IF(B12=0,0,D12/B12),0) -> 0
D13: =IFERROR(B13*C13,0) -> 0 | E13: =IFERROR(IF(B13=0,0,D13/B13),0) -> 0
D14: =IFERROR(B14*C14,0) -> 0 | E14: =IFERROR(IF(B14=0,0,D14/B14),0) -> 0
D15: =IFERROR(B15*C15,0) -> 0 | E15: =IFERROR(IF(B15=0,0,D15/B15),0) -> 0
D16: =IFERROR(B16*C16,0) -> 0 | E16: =IFERROR(IF(B16=0,0,D16/B16),0) -> 0
D17: =IFERROR(B17*C17,0) -> 0 | E17: =IFERROR(IF(B17=0,0,D17/B17),0) -> 0
... D203: =IFERROR(B203*C203,0) -> 0 | E203: =IFERROR(IF(B203=0,0,D203/B203),0) -> 0
A205: รวมทั้งหมด | B205: =SUM(B4:B203) -> 150 | D205: =SUM(D4:D203) -> 5105 | E205: =IFERROR(D205/B205,0) -> 34.033333

Sheet สต๊อก-Mycard
A1: 📦 สต๊อก-Mycard
A3: วันที่ | B3: มูลค่า / Point | C3: ต้นทุน (฿) | D3: ต้นทุนรวม (฿) | E3: ราคา/หน่วย | F3: แหล่งที่ซื้อ | G3: หมายเหตุ | H3: คงเหลือ
D4: =IFERROR(B4*C4,0) -> 0 | E4: =IFERROR(IF(B4=0,0,D4/B4),0) -> 0
D5: =IFERROR(B5*C5,0) -> 0 | E5: =IFERROR(IF(B5=0,0,D5/B5),0) -> 0
D6: =IFERROR(B6*C6,0) -> 0 | E6: =IFERROR(IF(B6=0,0,D6/B6),0) -> 0
D7: =IFERROR(B7*C7,0) -> 0 | E7: =IFERROR(IF(B7=0,0,D7/B7),0) -> 0
D8: =IFERROR(B8*C8,0) -> 0 | E8: =IFERROR(IF(B8=0,0,D8/B8),0) -> 0
D9: =IFERROR(B9*C9,0) -> 0 | E9: =IFERROR(IF(B9=0,0,D9/B9),0) -> 0
D10: =IFERROR(B10*C10,0) -> 0 | E10: =IFERROR(IF(B10=0,0,D10/B10),0) -> 0
D11: =IFERROR(B11*C11,0) -> 0 | E11: =IFERROR(IF(B11=0,0,D11/B11),0) -> 0
D12: =IFERROR(B12*C12,0) -> 0 | E12: =IFERROR(IF(B12=0,0,D12/B12),0) -> 0
D13: =IFERROR(B13*C13,0) -> 0 | E13: =IFERROR(IF(B13=0,0,D13/B13),0) -> 0
D14: =IFERROR(B14*C14,0) -> 0 | E14: =IFERROR(IF(B14=0,0,D14/B14),0) -> 0
D15: =IFERROR(B15*C15,0) -> 0 | E15: =IFERROR(IF(B15=0,0,D15/B15),0) -> 0
... D203: =IFERROR(B203*C203,0) -> 0 | E203: =IFERROR(IF(B203=0,0,D203/B203),0) -> 0
A205: รวมทั้งหมด | B205: =SUM(B4:B203) -> 0 | D205: =SUM(D4:D203) -> 0 | E205: =IFERROR(D205/B205,0) -> 0

Sheet สต๊อก-USDT-PHP
A1: 📦 สต๊อก-USDT-PHP
A3: วันที่ | B3: จำนวน (USDT/PHP) | C3: ต้นทุน (฿) | D3: ต้นทุนรวม (฿) | E3: ราคา/หน่วย | F3: แหล่งที่ซื้อ | G3: หมายเหตุ | H3: คงเหลือ
A4: 2026-04-22 | B4: 100 | C4: 36.2 | D4: =IFERROR(B4*C4,0) -> 3620 | E4: =IFERROR(IF(B4=0,0,D4/B4),0) -> 36.2 | F4: Over | G4: USDT
A5: 2026-04-26 | B5: 200 | C5: 0.62 | D5: =IFERROR(B5*C5,0) -> 124 | E5: =IFERROR(IF(B5=0,0,D5/B5),0) -> 0.62 | F5: 24BuyM | G5: PHP
D6: =IFERROR(B6*C6,0) -> 0 | E6: =IFERROR(IF(B6=0,0,D6/B6),0) -> 0
D7: =IFERROR(B7*C7,0) -> 0 | E7: =IFERROR(IF(B7=0,0,D7/B7),0) -> 0
D8: =IFERROR(B8*C8,0) -> 0 | E8: =IFERROR(IF(B8=0,0,D8/B8),0) -> 0
D9: =IFERROR(B9*C9,0) -> 0 | E9: =IFERROR(IF(B9=0,0,D9/B9),0) -> 0
D10: =IFERROR(B10*C10,0) -> 0 | E10: =IFERROR(IF(B10=0,0,D10/B10),0) -> 0
D11: =IFERROR(B11*C11,0) -> 0 | E11: =IFERROR(IF(B11=0,0,D11/B11),0) -> 0
D12: =IFERROR(B12*C12,0) -> 0 | E12: =IFERROR(IF(B12=0,0,D12/B12),0) -> 0
D13: =IFERROR(B13*C13,0) -> 0 | E13: =IFERROR(IF(B13=0,0,D13/B13),0) -> 0
D14: =IFERROR(B14*C14,0) -> 0 | E14: =IFERROR(IF(B14=0,0,D14/B14),0) -> 0
D15: =IFERROR(B15*C15,0) -> 0 | E15: =IFERROR(IF(B15=0,0,D15/B15),0) -> 0
D16: =IFERROR(B16*C16,0) -> 0 | E16: =IFERROR(IF(B16=0,0,D16/B16),0) -> 0
D17: =IFERROR(B17*C17,0) -> 0 | E17: =IFERROR(IF(B17=0,0,D17/B17),0) -> 0
... D203: =IFERROR(B203*C203,0) -> 0 | E203: =IFERROR(IF(B203=0,0,D203/B203),0) -> 0
A205: รวมทั้งหมด | B205: =SUM(B4:B203) -> 300 | D205: =SUM(D4:D203) -> 3744 | E205: =IFERROR(D205/B205,0) -> 12.48

Sheet Supply
A1: 🚚 Supply ส่งสินค้า — บันทึกผู้จัดส่งทั้ง 4 ราย
A3: วันที่ | B3: ผู้ขาย | C3: รายการ | D3: มูลค่าหน้าบัตร | E3: ต้นทุน (฿) | F3: สถานะ | G3: Tracking | H3: หมายเหตุ
A4: 2026-04-20 | B4: Kingpro | C4: iTunes 100$ x1 | D4: 100 | E4: 3300 | F4: ได้รับแล้ว
A5: 2026-04-22 | B5: 24BuyM | C5: iTunes 50$ x1 | D5: 50 | E5: 1700 | F5: ได้รับแล้ว
A6: 2026-04-25 | B6: จอนชาวไร่ | C6: iTunes 100$ x1 | D6: 100 | E6: 3280 | F6: ได้รับแล้ว
A7: 2026-04-21 | B7: Kingpro | C7: Razer Gold 50$ x1 | D7: 50 | E7: 1725 | F7: ได้รับแล้ว
A8: 2026-04-25 | B8: Over | C8: Razer Gold 100$ x1 | D8: 100 | E8: 3380 | F8: กำลังส่ง
A9: 2026-04-22 | B9: Over | C9: USDT 100 | D9: 100 | E9: 3620 | F9: ได้รับแล้ว
A10: 2026-04-26 | B10: 24BuyM | C10: PHP 200 | D10: 200 | E10: 124 | F10: รอจัดส่ง

Sheet วิเคราะห์ SKU
A1: 🧠 วิเคราะห์ SKU — เกมขายดี / กำไร / Trend
A3: อันดับ | B3: เกม | C3: จำนวน | D3: ยอดขาย (฿) | E3: ต้นทุน (฿) | F3: กำไร (฿) | G3: Margin %
A4: 1 | B4: =IFERROR(IF(LARGE(_agg!$G$2:$G$60,1)>=1,INDEX(_agg!$A$2:$A$60,MATCH(LARGE(_agg!$G$2:$G$60,1),_agg!$G$2:$G$60,0)),""),"") -> Genshin Impact | C4: =IF(B4="","",IFERROR(VLOOKUP(B4,_agg!$A$2:$F$60,2,FALSE()),"")) -> 3 | D4: =IF(B4="","",IFERROR(VLOOKUP(B4,_agg!$A$2:$F$60,3,FALSE()),"")) -> 1520 | E4: =IF(B4="","",IFERROR(VLOOKUP(B4,_agg!$A$2:$F$60,4,FALSE()),"")) -> 1280 | F4: =IF(B4="","",IFERROR(VLOOKUP(B4,_agg!$A$2:$F$60,5,FALSE()),"")) -> 240 | G4: =IF(B4="","",IFERROR(VLOOKUP(B4,_agg!$A$2:$F$60,6,FALSE()),"")) -> 0.15789474
A5: 2 | B5: =IFERROR(IF(LARGE(_agg!$G$2:$G$60,2)>=1,INDEX(_agg!$A$2:$A$60,MATCH(LARGE(_agg!$G$2:$G$60,2),_agg!$G$2:$G$60,0)),""),"") -> Free Fire | C5: =IF(B5="","",IFERROR(VLOOKUP(B5,_agg!$A$2:$F$60,2,FALSE()),"")) -> 3 | D5: =IF(B5="","",IFERROR(VLOOKUP(B5,_agg!$A$2:$F$60,3,FALSE()),"")) -> 290 | E5: =IF(B5="","",IFERROR(VLOOKUP(B5,_agg!$A$2:$F$60,4,FALSE()),"")) -> 215 | F5: =IF(B5="","",IFERROR(VLOOKUP(B5,_agg!$A$2:$F$60,5,FALSE()),"")) -> 75 | G5: =IF(B5="","",IFERROR(VLOOKUP(B5,_agg!$A$2:$F$60,6,FALSE()),"")) -> 0.25862069
A6: 3 | B6: =IFERROR(IF(LARGE(_agg!$G$2:$G$60,3)>=1,INDEX(_agg!$A$2:$A$60,MATCH(LARGE(_agg!$G$2:$G$60,3),_agg!$G$2:$G$60,0)),""),"") -> ROV | C6: =IF(B6="","",IFERROR(VLOOKUP(B6,_agg!$A$2:$F$60,2,FALSE()),"")) -> 2 | D6: =IF(B6="","",IFERROR(VLOOKUP(B6,_agg!$A$2:$F$60,3,FALSE()),"")) -> 255 | E6: =IF(B6="","",IFERROR(VLOOKUP(B6,_agg!$A$2:$F$60,4,FALSE()),"")) -> 190 | F6: =IF(B6="","",IFERROR(VLOOKUP(B6,_agg!$A$2:$F$60,5,FALSE()),"")) -> 65 | G6: =IF(B6="","",IFERROR(VLOOKUP(B6,_agg!$A$2:$F$60,6,FALSE()),"")) -> 0.25490196
A7: 4 | B7: =IFERROR(IF(LARGE(_agg!$G$2:$G$60,4)>=1,INDEX(_agg!$A$2:$A$60,MATCH(LARGE(_agg!$G$2:$G$60,4),_agg!$G$2:$G$60,0)),""),"") -> PUBG Mobile | C7: =IF(B7="","",IFERROR(VLOOKUP(B7,_agg!$A$2:$F$60,2,FALSE()),"")) -> 1 | D7: =IF(B7="","",IFERROR(VLOOKUP(B7,_agg!$A$2:$F$60,3,FALSE()),"")) -> 260 | E7: =IF(B7="","",IFERROR(VLOOKUP(B7,_agg!$A$2:$F$60,4,FALSE()),"")) -> 210 | F7: =IF(B7="","",IFERROR(VLOOKUP(B7,_agg!$A$2:$F$60,5,FALSE()),"")) -> 50 | G7: =IF(B7="","",IFERROR(VLOOKUP(B7,_agg!$A$2:$F$60,6,FALSE()),"")) -> 0.19230769
A8: 5 | B8: =IFERROR(IF(LARGE(_agg!$G$2:$G$60,5)>=1,INDEX(_agg!$A$2:$A$60,MATCH(LARGE(_agg!$G$2:$G$60,5),_agg!$G$2:$G$60,0)),""),"") -> Mobile Legends | C8: =IF(B8="","",IFERROR(VLOOKUP(B8,_agg!$A$2:$F$60,2,FALSE()),"")) -> 1 | D8: =IF(B8="","",IFERROR(VLOOKUP(B8,_agg!$A$2:$F$60,3,FALSE()),"")) -> 230 | E8: =IF(B8="","",IFERROR(VLOOKUP(B8,_agg!$A$2:$F$60,4,FALSE()),"")) -> 180 | F8: =IF(B8="","",IFERROR(VLOOKUP(B8,_agg!$A$2:$F$60,5,FALSE()),"")) -> 50 | G8: =IF(B8="","",IFERROR(VLOOKUP(B8,_agg!$A$2:$F$60,6,FALSE()),"")) -> 0.2173913
A9: 6 | B9: =IFERROR(IF(LARGE(_agg!$G$2:$G$60,6)>=1,INDEX(_agg!$A$2:$A$60,MATCH(LARGE(_agg!$G$2:$G$60,6),_agg!$G$2:$G$60,0)),""),"") | C9: =IF(B9="","",IFERROR(VLOOKUP(B9,_agg!$A$2:$F$60,2,FALSE()),"")) | D9: =IF(B9="","",IFERROR(VLOOKUP(B9,_agg!$A$2:$F$60,3,FALSE()),"")) | E9: =IF(B9="","",IFERROR(VLOOKUP(B9,_agg!$A$2:$F$60,4,FALSE()),"")) | F9: =IF(B9="","",IFERROR(VLOOKUP(B9,_agg!$A$2:$F$60,5,FALSE()),"")) | G9: =IF(B9="","",IFERROR(VLOOKUP(B9,_agg!$A$2:$F$60,6,FALSE()),""))
A10: 7 | B10: =IFERROR(IF(LARGE(_agg!$G$2:$G$60,7)>=1,INDEX(_agg!$A$2:$A$60,MATCH(LARGE(_agg!$G$2:$G$60,7),_agg!$G$2:$G$60,0)),""),"") | C10: =IF(B10="","",IFERROR(VLOOKUP(B10,_agg!$A$2:$F$60,2,FALSE()),"")) | D10: =IF(B10="","",IFERROR(VLOOKUP(B10,_agg!$A$2:$F$60,3,FALSE()),"")) | E10: =IF(B10="","",IFERROR(VLOOKUP(B10,_agg!$A$2:$F$60,4,FALSE()),"")) | F10: =IF(B10="","",IFERROR(VLOOKUP(B10,_agg!$A$2:$F$60,5,FALSE()),"")) | G10: =IF(B10="","",IFERROR(VLOOKUP(B10,_agg!$A$2:$F$60,6,FALSE()),""))
A11: 8 | B11: =IFERROR(IF(LARGE(_agg!$G$2:$G$60,8)>=1,INDEX(_agg!$A$2:$A$60,MATCH(LARGE(_agg!$G$2:$G$60,8),_agg!$G$2:$G$60,0)),""),"") | C11: =IF(B11="","",IFERROR(VLOOKUP(B11,_agg!$A$2:$F$60,2,FALSE()),"")) | D11: =IF(B11="","",IFERROR(VLOOKUP(B11,_agg!$A$2:$F$60,3,FALSE()),"")) | E11: =IF(B11="","",IFERROR(VLOOKUP(B11,_agg!$A$2:$F$60,4,FALSE()),"")) | F11: =IF(B11="","",IFERROR(VLOOKUP(B11,_agg!$A$2:$F$60,5,FALSE()),"")) | G11: =IF(B11="","",IFERROR(VLOOKUP(B11,_agg!$A$2:$F$60,6,FALSE()),""))
A12: 9 | B12: =IFERROR(IF(LARGE(_agg!$G$2:$G$60,9)>=1,INDEX(_agg!$A$2:$A$60,MATCH(LARGE(_agg!$G$2:$G$60,9),_agg!$G$2:$G$60,0)),""),"") | C12: =IF(B12="","",IFERROR(VLOOKUP(B12,_agg!$A$2:$F$60,2,FALSE()),"")) | D12: =IF(B12="","",IFERROR(VLOOKUP(B12,_agg!$A$2:$F$60,3,FALSE()),"")) | E12: =IF(B12="","",IFERROR(VLOOKUP(B12,_agg!$A$2:$F$60,4,FALSE()),"")) | F12: =IF(B12="","",IFERROR(VLOOKUP(B12,_agg!$A$2:$F$60,5,FALSE()),"")) | G12: =IF(B12="","",IFERROR(VLOOKUP(B12,_agg!$A$2:$F$60,6,FALSE()),""))
A13: 10 | B13: =IFERROR(IF(LARGE(_agg!$G$2:$G$60,10)>=1,INDEX(_agg!$A$2:$A$60,MATCH(LARGE(_agg!$G$2:$G$60,10),_agg!$G$2:$G$60,0)),""),"") | C13: =IF(B13="","",IFERROR(VLOOKUP(B13,_agg!$A$2:$F$60,2,FALSE()),"")) | D13: =IF(B13="","",IFERROR(VLOOKUP(B13,_agg!$A$2:$F$60,3,FALSE()),"")) | E13: =IF(B13="","",IFERROR(VLOOKUP(B13,_agg!$A$2:$F$60,4,FALSE()),"")) | F13: =IF(B13="","",IFERROR(VLOOKUP(B13,_agg!$A$2:$F$60,5,FALSE()),"")) | G13: =IF(B13="","",IFERROR(VLOOKUP(B13,_agg!$A$2:$F$60,6,FALSE()),""))
A14: 11 | B14: =IFERROR(IF(LARGE(_agg!$G$2:$G$60,11)>=1,INDEX(_agg!$A$2:$A$60,MATCH(LARGE(_agg!$G$2:$G$60,11),_agg!$G$2:$G$60,0)),""),"") | C14: =IF(B14="","",IFERROR(VLOOKUP(B14,_agg!$A$2:$F$60,2,FALSE()),"")) | D14: =IF(B14="","",IFERROR(VLOOKUP(B14,_agg!$A$2:$F$60,3,FALSE()),"")) | E14: =IF(B14="","",IFERROR(VLOOKUP(B14,_agg!$A$2:$F$60,4,FALSE()),"")) | F14: =IF(B14="","",IFERROR(VLOOKUP(B14,_agg!$A$2:$F$60,5,FALSE()),"")) | G14: =IF(B14="","",IFERROR(VLOOKUP(B14,_agg!$A$2:$F$60,6,FALSE()),""))
A15: 12 | B15: =IFERROR(IF(LARGE(_agg!$G$2:$G$60,12)>=1,INDEX(_agg!$A$2:$A$60,MATCH(LARGE(_agg!$G$2:$G$60,12),_agg!$G$2:$G$60,0)),""),"") | C15: =IF(B15="","",IFERROR(VLOOKUP(B15,_agg!$A$2:$F$60,2,FALSE()),"")) | D15: =IF(B15="","",IFERROR(VLOOKUP(B15,_agg!$A$2:$F$60,3,FALSE()),"")) | E15: =IF(B15="","",IFERROR(VLOOKUP(B15,_agg!$A$2:$F$60,4,FALSE()),"")) | F15: =IF(B15="","",IFERROR(VLOOKUP(B15,_agg!$A$2:$F$60,5,FALSE()),"")) | G15: =IF(B15="","",IFERROR(VLOOKUP(B15,_agg!$A$2:$F$60,6,FALSE()),""))
A16: 13 | B16: =IFERROR(IF(LARGE(_agg!$G$2:$G$60,13)>=1,INDEX(_agg!$A$2:$A$60,MATCH(LARGE(_agg!$G$2:$G$60,13),_agg!$G$2:$G$60,0)),""),"") | C16: =IF(B16="","",IFERROR(VLOOKUP(B16,_agg!$A$2:$F$60,2,FALSE()),"")) | D16: =IF(B16="","",IFERROR(VLOOKUP(B16,_agg!$A$2:$F$60,3,FALSE()),"")) | E16: =IF(B16="","",IFERROR(VLOOKUP(B16,_agg!$A$2:$F$60,4,FALSE()),"")) | F16: =IF(B16="","",IFERROR(VLOOKUP(B16,_agg!$A$2:$F$60,5,FALSE()),"")) | G16: =IF(B16="","",IFERROR(VLOOKUP(B16,_agg!$A$2:$F$60,6,FALSE()),""))
A17: 14 | B17: =IFERROR(IF(LARGE(_agg!$G$2:$G$60,14)>=1,INDEX(_agg!$A$2:$A$60,MATCH(LARGE(_agg!$G$2:$G$60,14),_agg!$G$2:$G$60,0)),""),"") | C17: =IF(B17="","",IFERROR(VLOOKUP(B17,_agg!$A$2:$F$60,2,FALSE()),"")) | D17: =IF(B17="","",IFERROR(VLOOKUP(B17,_agg!$A$2:$F$60,3,FALSE()),"")) | E17: =IF(B17="","",IFERROR(VLOOKUP(B17,_agg!$A$2:$F$60,4,FALSE()),"")) | F17: =IF(B17="","",IFERROR(VLOOKUP(B17,_agg!$A$2:$F$60,5,FALSE()),"")) | G17: =IF(B17="","",IFERROR(VLOOKUP(B17,_agg!$A$2:$F$60,6,FALSE()),""))
A18: 15 | B18: =IFERROR(IF(LARGE(_agg!$G$2:$G$60,15)>=1,INDEX(_agg!$A$2:$A$60,MATCH(LARGE(_agg!$G$2:$G$60,15),_agg!$G$2:$G$60,0)),""),"") | C18: =IF(B18="","",IFERROR(VLOOKUP(B18,_agg!$A$2:$F$60,2,FALSE()),"")) | D18: =IF(B18="","",IFERROR(VLOOKUP(B18,_agg!$A$2:$F$60,3,FALSE()),"")) | E18: =IF(B18="","",IFERROR(VLOOKUP(B18,_agg!$A$2:$F$60,4,FALSE()),"")) | F18: =IF(B18="","",IFERROR(VLOOKUP(B18,_agg!$A$2:$F$60,5,FALSE()),"")) | G18: =IF(B18="","",IFERROR(VLOOKUP(B18,_agg!$A$2:$F$60,6,FALSE()),""))
A19: 16 | B19: =IFERROR(IF(LARGE(_agg!$G$2:$G$60,16)>=1,INDEX(_agg!$A$2:$A$60,MATCH(LARGE(_agg!$G$2:$G$60,16),_agg!$G$2:$G$60,0)),""),"") | C19: =IF(B19="","",IFERROR(VLOOKUP(B19,_agg!$A$2:$F$60,2,FALSE()),"")) | D19: =IF(B19="","",IFERROR(VLOOKUP(B19,_agg!$A$2:$F$60,3,FALSE()),"")) | E19: =IF(B19="","",IFERROR(VLOOKUP(B19,_agg!$A$2:$F$60,4,FALSE()),"")) | F19: =IF(B19="","",IFERROR(VLOOKUP(B19,_agg!$A$2:$F$60,5,FALSE()),"")) | G19: =IF(B19="","",IFERROR(VLOOKUP(B19,_agg!$A$2:$F$60,6,FALSE()),""))
A20: 17 | B20: =IFERROR(IF(LARGE(_agg!$G$2:$G$60,17)>=1,INDEX(_agg!$A$2:$A$60,MATCH(LARGE(_agg!$G$2:$G$60,17),_agg!$G$2:$G$60,0)),""),"") | C20: =IF(B20="","",IFERROR(VLOOKUP(B20,_agg!$A$2:$F$60,2,FALSE()),"")) | D20: =IF(B20="","",IFERROR(VLOOKUP(B20,_agg!$A$2:$F$60,3,FALSE()),"")) | E20: =IF(B20="","",IFERROR(VLOOKUP(B20,_agg!$A$2:$F$60,4,FALSE()),"")) | F20: =IF(B20="","",IFERROR(VLOOKUP(B20,_agg!$A$2:$F$60,5,FALSE()),"")) | G20: =IF(B20="","",IFERROR(VLOOKUP(B20,_agg!$A$2:$F$60,6,FALSE()),""))
A21: 18 | B21: =IFERROR(IF(LARGE(_agg!$G$2:$G$60,18)>=1,INDEX(_agg!$A$2:$A$60,MATCH(LARGE(_agg!$G$2:$G$60,18),_agg!$G$2:$G$60,0)),""),"") | C21: =IF(B21="","",IFERROR(VLOOKUP(B21,_agg!$A$2:$F$60,2,FALSE()),"")) | D21: =IF(B21="","",IFERROR(VLOOKUP(B21,_agg!$A$2:$F$60,3,FALSE()),"")) | E21: =IF(B21="","",IFERROR(VLOOKUP(B21,_agg!$A$2:$F$60,4,FALSE()),"")) | F21: =IF(B21="","",IFERROR(VLOOKUP(B21,_agg!$A$2:$F$60,5,FALSE()),"")) | G21: =IF(B21="","",IFERROR(VLOOKUP(B21,_agg!$A$2:$F$60,6,FALSE()),""))
A22: 19 | B22: =IFERROR(IF(LARGE(_agg!$G$2:$G$60,19)>=1,INDEX(_agg!$A$2:$A$60,MATCH(LARGE(_agg!$G$2:$G$60,19),_agg!$G$2:$G$60,0)),""),"") | C22: =IF(B22="","",IFERROR(VLOOKUP(B22,_agg!$A$2:$F$60,2,FALSE()),"")) | D22: =IF(B22="","",IFERROR(VLOOKUP(B22,_agg!$A$2:$F$60,3,FALSE()),"")) | E22: =IF(B22="","",IFERROR(VLOOKUP(B22,_agg!$A$2:$F$60,4,FALSE()),"")) | F22: =IF(B22="","",IFERROR(VLOOKUP(B22,_agg!$A$2:$F$60,5,FALSE()),"")) | G22: =IF(B22="","",IFERROR(VLOOKUP(B22,_agg!$A$2:$F$60,6,FALSE()),""))
A23: 20 | B23: =IFERROR(IF(LARGE(_agg!$G$2:$G$60,20)>=1,INDEX(_agg!$A$2:$A$60,MATCH(LARGE(_agg!$G$2:$G$60,20),_agg!$G$2:$G$60,0)),""),"") | C23: =IF(B23="","",IFERROR(VLOOKUP(B23,_agg!$A$2:$F$60,2,FALSE()),"")) | D23: =IF(B23="","",IFERROR(VLOOKUP(B23,_agg!$A$2:$F$60,3,FALSE()),"")) | E23: =IF(B23="","",IFERROR(VLOOKUP(B23,_agg!$A$2:$F$60,4,FALSE()),"")) | F23: =IF(B23="","",IFERROR(VLOOKUP(B23,_agg!$A$2:$F$60,5,FALSE()),"")) | G23: =IF(B23="","",IFERROR(VLOOKUP(B23,_agg!$A$2:$F$60,6,FALSE()),""))
A26: 📊 บทวิเคราะห์อัตโนมัติ
A27: ยอดขายรวม: | B27: =ภาพรวม!D4 -> 2555 | C27: ต้นทุนรวม: | D27: =ภาพรวม!B4 -> 2075 | E27: กำไรรวม: | F27: =ภาพรวม!F4 -> 480 | G27: =IFERROR(F27/B27,0) -> 0.18786693
A29: ="• ร้านมีรายการขายทั้งหมด "&TEXT(ภาพรวม!H4,"#,##0")&" รายการ ยอดขายรวม ฿"&TEXT(ภาพรวม!D4,"#,##0")&" ทำกำไรได้ ฿"&TEXT(ภาพรวม!F4,"#,##0")&" (Margin "&TEXT(ภาพรวม!D6,"0.0%")&")" -> • ร้านมีรายการขายทั้งหมด 10 รายการ ยอดขายรวม ฿2,555 ทำกำไรได้ ฿480 (Margin 18.8%)
A30: ="• เกมที่ขายบ่อยที่สุดคือ "&CHAR(34)&B4&CHAR(34)&" จำนวน "&TEXT(C4,"#,##0")&" รายการ ทำกำไร ฿"&TEXT(F4,"#,##0") -> • เกมที่ขายบ่อยที่สุดคือ "Genshin Impact" จำนวน 3 รายการ ทำกำไร ฿240
A31: ="• เกมที่ทำกำไรสูงสุดคือ "&CHAR(34)&IFERROR(INDEX(_agg!A2:A60,MATCH(MAX(_agg!E2:E60),_agg!E2:E60,0)),"-")&CHAR(34)&" รวม ฿"&TEXT(IFERROR(MAX(_agg!E2:E60),0),"#,##0") -> • เกมที่ทำกำไรสูงสุดคือ "Genshin Impact" รวม ฿240
A32: ="• สต๊อกที่ใช้เติมเยอะที่สุด (ตามจำนวนครั้ง): "&IFERROR(INDEX(_agg!H2:H6,MATCH(MAX(_agg!I2:I6),_agg!I2:I6,0))&" ("&MAX(_agg!I2:I6)&" ครั้ง)","-") -> • สต๊อกที่ใช้เติมเยอะที่สุด (ตามจำนวนครั้ง): iTunes (3 ครั้ง)
A33: ="• ช่องทางการโอนยอดนิยม: "&IFERROR(INDEX(_agg!K2:K10,MATCH(MAX(_agg!L2:L10),_agg!L2:L10,0))&" ("&MAX(_agg!L2:L10)&" ครั้ง)","-") -> • ช่องทางการโอนยอดนิยม: TrueWallet (3 ครั้ง)
A34: ="• ราคาขายเฉลี่ย/รายการ: ฿"&TEXT(IFERROR(ภาพรวม!D4/ภาพรวม!H4,0),"#,##0.00")&" — กำไรเฉลี่ย/รายการ: ฿"&TEXT(IFERROR(ภาพรวม!F4/ภาพรวม!H4,0),"#,##0.00") -> • ราคาขายเฉลี่ย/รายการ: ฿255.50 — กำไรเฉลี่ย/รายการ: ฿48.00
A36: ="💡 ข้อเสนอแนะ:" -> 💡 ข้อเสนอแนะ:
A37: ="• เน้นโปรโมตและจัดสต๊อก "&CHAR(34)&B4&CHAR(34)&" ให้พอใช้ในช่วง 7 วันข้างหน้า" -> • เน้นโปรโมตและจัดสต๊อก "Genshin Impact" ให้พอใช้ในช่วง 7 วันข้างหน้า
A38: =IF(ภาพรวม!D6<0.1,"• Margin ต่ำกว่า 10% — ควรเจรจาต้นทุน Supply ให้ถูกลง หรือปรับราคาขายขึ้น 5-10%","• Margin อยู่ในเกณฑ์ดี ควรรักษาสมดุลต้นทุนต่อไป") -> • Margin อยู่ในเกณฑ์ดี ควรรักษาสมดุลต้นทุนต่อไป
A39: ="• ทบทวนสต๊อก iTunes/Razer/USDT ที่ราคาเฉลี่ยสูง และเปรียบเทียบราคาจาก Supplier ทั้ง 4 ราย เพื่อหาแหล่งที่ถูกสุด" -> • ทบทวนสต๊อก iTunes/Razer/USDT ที่ราคาเฉลี่ยสูง และเปรียบเทียบราคาจาก Supplier ทั้ง 4 ราย เพื่อหาแหล่งที่ถูกสุด

Sheet รายชื่อเกม
A1: 🎯 รายชื่อเกม / คำนวนต้นทุน
A3: เกม | B3: หมวด | C3: จำนวนรายการ | D3: ต้นทุนเฉลี่ย | E3: ราคาขายเฉลี่ย | F3: กำไรเฉลี่ย | G3: Margin % | H3: ราคาขายแนะนำ (+25%)
A4: =IF(IFERROR(_agg!B2,0)>=1,IFERROR(_agg!A2,""),"") -> Free Fire | C4: =IF(A4="","",_agg!B2) -> 3 | D4: =IF(A4="","",_agg!D2/_agg!B2) -> 71.666667 | E4: =IF(A4="","",_agg!C2/_agg!B2) -> 96.666667 | F4: =IF(A4="","",E4-D4) -> 25 | G4: =IF(A4="","",F4/E4) -> 0.25862069 | H4: =IF(A4="","",D4/(1-0.25)) -> 95.555556
A5: =IF(IFERROR(_agg!B3,0)>=1,IFERROR(_agg!A3,""),"") -> ROV | C5: =IF(A5="","",_agg!B3) -> 2 | D5: =IF(A5="","",_agg!D3/_agg!B3) -> 95 | E5: =IF(A5="","",_agg!C3/_agg!B3) -> 127.5 | F5: =IF(A5="","",E5-D5) -> 32.5 | G5: =IF(A5="","",F5/E5) -> 0.25490196 | H5: =IF(A5="","",D5/(1-0.25)) -> 126.66667
A6: =IF(IFERROR(_agg!B4,0)>=1,IFERROR(_agg!A4,""),"") -> Genshin Impact | C6: =IF(A6="","",_agg!B4) -> 3 | D6: =IF(A6="","",_agg!D4/_agg!B4) -> 426.66667 | E6: =IF(A6="","",_agg!C4/_agg!B4) -> 506.66667 | F6: =IF(A6="","",E6-D6) -> 80 | G6: =IF(A6="","",F6/E6) -> 0.15789474 | H6: =IF(A6="","",D6/(1-0.25)) -> 568.88889
A7: =IF(IFERROR(_agg!B5,0)>=1,IFERROR(_agg!A5,""),"") -> Mobile Legends | C7: =IF(A7="","",_agg!B5) -> 1 | D7: =IF(A7="","",_agg!D5/_agg!B5) -> 180 | E7: =IF(A7="","",_agg!C5/_agg!B5) -> 230 | F7: =IF(A7="","",E7-D7) -> 50 | G7: =IF(A7="","",F7/E7) -> 0.2173913 | H7: =IF(A7="","",D7/(1-0.25)) -> 240
A8: =IF(IFERROR(_agg!B6,0)>=1,IFERROR(_agg!A6,""),"") -> PUBG Mobile | C8: =IF(A8="","",_agg!B6) -> 1 | D8: =IF(A8="","",_agg!D6/_agg!B6) -> 210 | E8: =IF(A8="","",_agg!C6/_agg!B6) -> 260 | F8: =IF(A8="","",E8-D8) -> 50 | G8: =IF(A8="","",F8/E8) -> 0.19230769 | H8: =IF(A8="","",D8/(1-0.25)) -> 280
A9: =IF(IFERROR(_agg!B7,0)>=1,IFERROR(_agg!A7,""),"") | C9: =IF(A9="","",_agg!B7) | D9: =IF(A9="","",_agg!D7/_agg!B7) | E9: =IF(A9="","",_agg!C7/_agg!B7) | F9: =IF(A9="","",E9-D9) | G9: =IF(A9="","",F9/E9) | H9: =IF(A9="","",D9/(1-0.25))
A10: =IF(IFERROR(_agg!B8,0)>=1,IFERROR(_agg!A8,""),"") | C10: =IF(A10="","",_agg!B8) | D10: =IF(A10="","",_agg!D8/_agg!B8) | E10: =IF(A10="","",_agg!C8/_agg!B8) | F10: =IF(A10="","",E10-D10) | G10: =IF(A10="","",F10/E10) | H10: =IF(A10="","",D10/(1-0.25))
A11: =IF(IFERROR(_agg!B9,0)>=1,IFERROR(_agg!A9,""),"") | C11: =IF(A11="","",_agg!B9) | D11: =IF(A11="","",_agg!D9/_agg!B9) | E11: =IF(A11="","",_agg!C9/_agg!B9) | F11: =IF(A11="","",E11-D11) | G11: =IF(A11="","",F11/E11) | H11: =IF(A11="","",D11/(1-0.25))
A12: =IF(IFERROR(_agg!B10,0)>=1,IFERROR(_agg!A10,""),"") | C12: =IF(A12="","",_agg!B10) | D12: =IF(A12="","",_agg!D10/_agg!B10) | E12: =IF(A12="","",_agg!C10/_agg!B10) | F12: =IF(A12="","",E12-D12) | G12: =IF(A12="","",F12/E12) | H12: =IF(A12="","",D12/(1-0.25))
A13: =IF(IFERROR(_agg!B11,0)>=1,IFERROR(_agg!A11,""),"") | C13: =IF(A13="","",_agg!B11) | D13: =IF(A13="","",_agg!D11/_agg!B11) | E13: =IF(A13="","",_agg!C11/_agg!B11) | F13: =IF(A13="","",E13-D13) | G13: =IF(A13="","",F13/E13) | H13: =IF(A13="","",D13/(1-0.25))
A14: =IF(IFERROR(_agg!B12,0)>=1,IFERROR(_agg!A12,""),"") | C14: =IF(A14="","",_agg!B12) | D14: =IF(A14="","",_agg!D12/_agg!B12) | E14: =IF(A14="","",_agg!C12/_agg!B12) | F14: =IF(A14="","",E14-D14) | G14: =IF(A14="","",F14/E14) | H14: =IF(A14="","",D14/(1-0.25))
A15: =IF(IFERROR(_agg!B13,0)>=1,IFERROR(_agg!A13,""),"") | C15: =IF(A15="","",_agg!B13) | D15: =IF(A15="","",_agg!D13/_agg!B13) | E15: =IF(A15="","",_agg!C13/_agg!B13) | F15: =IF(A15="","",E15-D15) | G15: =IF(A15="","",F15/E15) | H15: =IF(A15="","",D15/(1-0.25))
... A63: =IF(IFERROR(_agg!B61,0)>=1,IFERROR(_agg!A61,""),"") | C63: =IF(A63="","",_agg!B61) | D63: =IF(A63="","",_agg!D61/_agg!B61) | E63: =IF(A63="","",_agg!C61/_agg!B61) | F63: =IF(A63="","",E63-D63) | G63: =IF(A63="","",F63/E63) | H63: =IF(A63="","",D63/(1-0.25))
A65: 🧮 คำนวนต้นทุน → ราคาขาย
A67: ต้นทุน (฿) | B67: 100
A68: % กำไรที่ต้องการ | B68: 0.25
A69: ราคาขายแนะนำ | B69: =IFERROR(B67/(1-B68),0) -> 133.33333
A70: กำไร/รายการ | B70: =B69-B67 -> 33.333333
A72: ตารางอัตรากำไรอ้างอิง
A73: % กำไร | B73: ตัวคูณ (×) | C73: ราคาขายแนะนำ
A74: 0.1 | B74: =1/(1-A74) -> 1.1111111 | C74: =$B$67*B74 -> 111.11111
A75: 0.15 | B75: =1/(1-A75) -> 1.1764706 | C75: =$B$67*B75 -> 117.64706
A76: 0.2 | B76: =1/(1-A76) -> 1.25 | C76: =$B$67*B76 -> 125
A77: 0.25 | B77: =1/(1-A77) -> 1.3333333 | C77: =$B$67*B77 -> 133.33333
A78: 0.3 | B78: =1/(1-A78) -> 1.4285714 | C78: =$B$67*B78 -> 142.85714
A79: 0.4 | B79: =1/(1-A79) -> 1.6666667 | C79: =$B$67*B79 -> 166.66667
A80: 0.5 | B80: =1/(1-A80) -> 2 | C80: =$B$67*B80 -> 200

Sheet _agg
A1: เกม | B1: จำนวน | C1: ยอดขาย | D1: ต้นทุน | E1: กำไร | F1: Margin | H1: สต๊อก | I1: นับ | K1: ช่องทาง | L1: นับ
A2: Free Fire | B2: =COUNTIF(ประวัติการขาย!D4:D203,A2) -> 3 | C2: =SUMIF(ประวัติการขาย!D4:D203,A2,ประวัติการขาย!H4:H203) -> 290 | D2: =SUMIF(ประวัติการขาย!D4:D203,A2,ประวัติการขาย!G4:G203) -> 215 | E2: =C2-D2 -> 75 | F2: =IFERROR(E2/C2,0) -> 0.25862069 | G2: =B2+ROW()/10000 -> 3.0002 | H2: iTunes | I2: =COUNTIF(ประวัติการขาย!F4:F203,"iTunes") -> 3 | K2: TrueWallet | L2: =COUNTIF(ประวัติการขาย!E4:E203,"TrueWallet") -> 3 | N2: =E2+ROW()/10000 -> 75.0002
A3: ROV | B3: =COUNTIF(ประวัติการขาย!D4:D203,A3) -> 2 | C3: =SUMIF(ประวัติการขาย!D4:D203,A3,ประวัติการขาย!H4:H203) -> 255 | D3: =SUMIF(ประวัติการขาย!D4:D203,A3,ประวัติการขาย!G4:G203) -> 190 | E3: =C3-D3 -> 65 | F3: =IFERROR(E3/C3,0) -> 0.25490196 | G3: =B3+ROW()/10000 -> 2.0003 | H3: Razer | I3: =COUNTIF(ประวัติการขาย!F4:F203,"Razer") -> 3 | K3: SCB | L3: =COUNTIF(ประวัติการขาย!E4:E203,"SCB") -> 1 | N3: =E3+ROW()/10000 -> 65.0003
A4: Genshin Impact | B4: =COUNTIF(ประวัติการขาย!D4:D203,A4) -> 3 | C4: =SUMIF(ประวัติการขาย!D4:D203,A4,ประวัติการขาย!H4:H203) -> 1520 | D4: =SUMIF(ประวัติการขาย!D4:D203,A4,ประวัติการขาย!G4:G203) -> 1280 | E4: =C4-D4 -> 240 | F4: =IFERROR(E4/C4,0) -> 0.15789474 | G4: =B4+ROW()/10000 -> 3.0004 | H4: Mycard | I4: =COUNTIF(ประวัติการขาย!F4:F203,"Mycard") -> 1 | K4: KBank | L4: =COUNTIF(ประวัติการขาย!E4:E203,"KBank") -> 1 | N4: =E4+ROW()/10000 -> 240.0004
A5: Mobile Legends | B5: =COUNTIF(ประวัติการขาย!D4:D203,A5) -> 1 | C5: =SUMIF(ประวัติการขาย!D4:D203,A5,ประวัติการขาย!H4:H203) -> 230 | D5: =SUMIF(ประวัติการขาย!D4:D203,A5,ประวัติการขาย!G4:G203) -> 180 | E5: =C5-D5 -> 50 | F5: =IFERROR(E5/C5,0) -> 0.2173913 | G5: =B5+ROW()/10000 -> 1.0005 | H5: USDT/PHP | I5: =COUNTIF(ประวัติการขาย!F4:F203,"USDT/PHP") -> 3 | K5: Krungthai | L5: =COUNTIF(ประวัติการขาย!E4:E203,"Krungthai") -> 0 | N5: =E5+ROW()/10000 -> 50.0005
A6: PUBG Mobile | B6: =COUNTIF(ประวัติการขาย!D4:D203,A6) -> 1 | C6: =SUMIF(ประวัติการขาย!D4:D203,A6,ประวัติการขาย!H4:H203) -> 260 | D6: =SUMIF(ประวัติการขาย!D4:D203,A6,ประวัติการขาย!G4:G203) -> 210 | E6: =C6-D6 -> 50 | F6: =IFERROR(E6/C6,0) -> 0.19230769 | G6: =B6+ROW()/10000 -> 1.0006 | H6: เติมตรง | I6: =COUNTIF(ประวัติการขาย!F4:F203,"เติมตรง") -> 0 | K6: BBL | L6: =COUNTIF(ประวัติการขาย!E4:E203,"BBL") -> 1 | N6: =E6+ROW()/10000 -> 50.0006
A7: Honor of Kings | B7: =COUNTIF(ประวัติการขาย!D4:D203,A7) -> 0 | C7: =SUMIF(ประวัติการขาย!D4:D203,A7,ประวัติการขาย!H4:H203) -> 0 | D7: =SUMIF(ประวัติการขาย!D4:D203,A7,ประวัติการขาย!G4:G203) -> 0 | E7: =C7-D7 -> 0 | F7: =IFERROR(E7/C7,0) -> 0 | G7: =B7+ROW()/10000 -> 0.0007 | K7: PromptPay | L7: =COUNTIF(ประวัติการขาย!E4:E203,"PromptPay") -> 1 | N7: =E7+ROW()/10000 -> 0.0007
A8: Valorant | B8: =COUNTIF(ประวัติการขาย!D4:D203,A8) -> 0 | C8: =SUMIF(ประวัติการขาย!D4:D203,A8,ประวัติการขาย!H4:H203) -> 0 | D8: =SUMIF(ประวัติการขาย!D4:D203,A8,ประวัติการขาย!G4:G203) -> 0 | E8: =C8-D8 -> 0 | F8: =IFERROR(E8/C8,0) -> 0 | G8: =B8+ROW()/10000 -> 0.0008 | K8: USDT | L8: =COUNTIF(ประวัติการขาย!E4:E203,"USDT") -> 3 | N8: =E8+ROW()/10000 -> 0.0008
A9: Call of Duty Mobile | B9: =COUNTIF(ประวัติการขาย!D4:D203,A9) -> 0 | C9: =SUMIF(ประวัติการขาย!D4:D203,A9,ประวัติการขาย!H4:H203) -> 0 | D9: =SUMIF(ประวัติการขาย!D4:D203,A9,ประวัติการขาย!G4:G203) -> 0 | E9: =C9-D9 -> 0 | F9: =IFERROR(E9/C9,0) -> 0 | G9: =B9+ROW()/10000 -> 0.0009 | K9: เงินสด | L9: =COUNTIF(ประวัติการขาย!E4:E203,"เงินสด") -> 0 | N9: =E9+ROW()/10000 -> 0.0009
A10: Identity V | B10: =COUNTIF(ประวัติการขาย!D4:D203,A10) -> 0 | C10: =SUMIF(ประวัติการขาย!D4:D203,A10,ประวัติการขาย!H4:H203) -> 0 | D10: =SUMIF(ประวัติการขาย!D4:D203,A10,ประวัติการขาย!G4:G203) -> 0 | E10: =C10-D10 -> 0 | F10: =IFERROR(E10/C10,0) -> 0 | G10: =B10+ROW()/10000 -> 0.001 | K10: อื่นๆ | L10: =COUNTIF(ประวัติการขาย!E4:E203,"อื่นๆ") -> 0 | N10: =E10+ROW()/10000 -> 0.001
A11: Lineage W | B11: =COUNTIF(ประวัติการขาย!D4:D203,A11) -> 0 | C11: =SUMIF(ประวัติการขาย!D4:D203,A11,ประวัติการขาย!H4:H203) -> 0 | D11: =SUMIF(ประวัติการขาย!D4:D203,A11,ประวัติการขาย!G4:G203) -> 0 | E11: =C11-D11 -> 0 | F11: =IFERROR(E11/C11,0) -> 0 | G11: =B11+ROW()/10000 -> 0.0011 | N11: =E11+ROW()/10000 -> 0.0011
A12: Ragnarok X | B12: =COUNTIF(ประวัติการขาย!D4:D203,A12) -> 0 | C12: =SUMIF(ประวัติการขาย!D4:D203,A12,ประวัติการขาย!H4:H203) -> 0 | D12: =SUMIF(ประวัติการขาย!D4:D203,A12,ประวัติการขาย!G4:G203) -> 0 | E12: =C12-D12 -> 0 | F12: =IFERROR(E12/C12,0) -> 0 | G12: =B12+ROW()/10000 -> 0.0012 | N12: =E12+ROW()/10000 -> 0.0012
A13: Roblox | B13: =COUNTIF(ประวัติการขาย!D4:D203,A13) -> 0 | C13: =SUMIF(ประวัติการขาย!D4:D203,A13,ประวัติการขาย!H4:H203) -> 0 | D13: =SUMIF(ประวัติการขาย!D4:D203,A13,ประวัติการขาย!G4:G203) -> 0 | E13: =C13-D13 -> 0 | F13: =IFERROR(E13/C13,0) -> 0 | G13: =B13+ROW()/10000 -> 0.0013 | N13: =E13+ROW()/10000 -> 0.0013
A14: Minecraft | B14: =COUNTIF(ประวัติการขาย!D4:D203,A14) -> 0 | C14: =SUMIF(ประวัติการขาย!D4:D203,A14,ประวัติการขาย!H4:H203) -> 0 | D14: =SUMIF(ประวัติการขาย!D4:D203,A14,ประวัติการขาย!G4:G203) -> 0 | E14: =C14-D14 -> 0 | F14: =IFERROR(E14/C14,0) -> 0 | G14: =B14+ROW()/10000 -> 0.0014 | N14: =E14+ROW()/10000 -> 0.0014
A15: Steam Wallet | B15: =COUNTIF(ประวัติการขาย!D4:D203,A15) -> 0 | C15: =SUMIF(ประวัติการขาย!D4:D203,A15,ประวัติการขาย!H4:H203) -> 0 | D15: =SUMIF(ประวัติการขาย!D4:D203,A15,ประวัติการขาย!G4:G203) -> 0 | E15: =C15-D15 -> 0 | F15: =IFERROR(E15/C15,0) -> 0 | G15: =B15+ROW()/10000 -> 0.0015 | N15: =E15+ROW()/10000 -> 0.0015
A16: Apple Gift Card | B16: =COUNTIF(ประวัติการขาย!D4:D203,A16) -> 0 | C16: =SUMIF(ประวัติการขาย!D4:D203,A16,ประวัติการขาย!H4:H203) -> 0 | D16: =SUMIF(ประวัติการขาย!D4:D203,A16,ประวัติการขาย!G4:G203) -> 0 | E16: =C16-D16 -> 0 | F16: =IFERROR(E16/C16,0) -> 0 | G16: =B16+ROW()/10000 -> 0.0016 | N16: =E16+ROW()/10000 -> 0.0016
A17: Razer Gold Pin | B17: =COUNTIF(ประวัติการขาย!D4:D203,A17) -> 0 | C17: =SUMIF(ประวัติการขาย!D4:D203,A17,ประวัติการขาย!H4:H203) -> 0 | D17: =SUMIF(ประวัติการขาย!D4:D203,A17,ประวัติการขาย!G4:G203) -> 0 | E17: =C17-D17 -> 0 | F17: =IFERROR(E17/C17,0) -> 0 | G17: =B17+ROW()/10000 -> 0.0017 | N17: =E17+ROW()/10000 -> 0.0017
A18: Mycard | B18: =COUNTIF(ประวัติการขาย!D4:D203,A18) -> 0 | C18: =SUMIF(ประวัติการขาย!D4:D203,A18,ประวัติการขาย!H4:H203) -> 0 | D18: =SUMIF(ประวัติการขาย!D4:D203,A18,ประวัติการขาย!G4:G203) -> 0 | E18: =C18-D18 -> 0 | F18: =IFERROR(E18/C18,0) -> 0 | G18: =B18+ROW()/10000 -> 0.0018 | N18: =E18+ROW()/10000 -> 0.0018
A19: Garena Shells | B19: =COUNTIF(ประวัติการขาย!D4:D203,A19) -> 0 | C19: =SUMIF(ประวัติการขาย!D4:D203,A19,ประวัติการขาย!H4:H203) -> 0 | D19: =SUMIF(ประวัติการขาย!D4:D203,A19,ประวัติการขาย!G4:G203) -> 0 | E19: =C19-D19 -> 0 | F19: =IFERROR(E19/C19,0) -> 0 | G19: =B19+ROW()/10000 -> 0.0019 | N19: =E19+ROW()/10000 -> 0.0019
A20: Wild Rift | B20: =COUNTIF(ประวัติการขาย!D4:D203,A20) -> 0 | C20: =SUMIF(ประวัติการขาย!D4:D203,A20,ประวัติการขาย!H4:H203) -> 0 | D20: =SUMIF(ประวัติการขาย!D4:D203,A20,ประวัติการขาย!G4:G203) -> 0 | E20: =C20-D20 -> 0 | F20: =IFERROR(E20/C20,0) -> 0 | G20: =B20+ROW()/10000 -> 0.002 | N20: =E20+ROW()/10000 -> 0.002
A21: Arena Breakout | B21: =COUNTIF(ประวัติการขาย!D4:D203,A21) -> 0 | C21: =SUMIF(ประวัติการขาย!D4:D203,A21,ประวัติการขาย!H4:H203) -> 0 | D21: =SUMIF(ประวัติการขาย!D4:D203,A21,ประวัติการขาย!G4:G203) -> 0 | E21: =C21-D21 -> 0 | F21: =IFERROR(E21/C21,0) -> 0 | G21: =B21+ROW()/10000 -> 0.0021 | N21: =E21+ROW()/10000 -> 0.0021
B22: =IF(A22="",0,COUNTIF(ประวัติการขาย!D4:D203,A22)) -> 0 | C22: =IF(A22="",0,SUMIF(ประวัติการขาย!D4:D203,A22,ประวัติการขาย!H4:H203)) -> 0 | D22: =IF(A22="",0,SUMIF(ประวัติการขาย!D4:D203,A22,ประวัติการขาย!G4:G203)) -> 0 | E22: =IF(A22="",0,C22-D22) -> 0 | F22: =IFERROR(E22/C22,0) -> 0 | G22: =B22+ROW()/10000 -> 0.0022 | N22: =E22+ROW()/10000 -> 0.0022
B23: =IF(A23="",0,COUNTIF(ประวัติการขาย!D4:D203,A23)) -> 0 | C23: =IF(A23="",0,SUMIF(ประวัติการขาย!D4:D203,A23,ประวัติการขาย!H4:H203)) -> 0 | D23: =IF(A23="",0,SUMIF(ประวัติการขาย!D4:D203,A23,ประวัติการขาย!G4:G203)) -> 0 | E23: =IF(A23="",0,C23-D23) -> 0 | F23: =IFERROR(E23/C23,0) -> 0 | G23: =B23+ROW()/10000 -> 0.0023 | N23: =E23+ROW()/10000 -> 0.0023
B24: =IF(A24="",0,COUNTIF(ประวัติการขาย!D4:D203,A24)) -> 0 | C24: =IF(A24="",0,SUMIF(ประวัติการขาย!D4:D203,A24,ประวัติการขาย!H4:H203)) -> 0 | D24: =IF(A24="",0,SUMIF(ประวัติการขาย!D4:D203,A24,ประวัติการขาย!G4:G203)) -> 0 | E24: =IF(A24="",0,C24-D24) -> 0 | F24: =IFERROR(E24/C24,0) -> 0 | G24: =B24+ROW()/10000 -> 0.0024 | N24: =E24+ROW()/10000 -> 0.0024
B25: =IF(A25="",0,COUNTIF(ประวัติการขาย!D4:D203,A25)) -> 0 | C25: =IF(A25="",0,SUMIF(ประวัติการขาย!D4:D203,A25,ประวัติการขาย!H4:H203)) -> 0 | D25: =IF(A25="",0,SUMIF(ประวัติการขาย!D4:D203,A25,ประวัติการขาย!G4:G203)) -> 0 | E25: =IF(A25="",0,C25-D25) -> 0 | F25: =IFERROR(E25/C25,0) -> 0 | G25: =B25+ROW()/10000 -> 0.0025 | N25: =E25+ROW()/10000 -> 0.0025
B26: =IF(A26="",0,COUNTIF(ประวัติการขาย!D4:D203,A26)) -> 0 | C26: =IF(A26="",0,SUMIF(ประวัติการขาย!D4:D203,A26,ประวัติการขาย!H4:H203)) -> 0 | D26: =IF(A26="",0,SUMIF(ประวัติการขาย!D4:D203,A26,ประวัติการขาย!G4:G203)) -> 0 | E26: =IF(A26="",0,C26-D26) -> 0 | F26: =IFERROR(E26/C26,0) -> 0 | G26: =B26+ROW()/10000 -> 0.0026 | N26: =E26+ROW()/10000 -> 0.0026
B27: =IF(A27="",0,COUNTIF(ประวัติการขาย!D4:D203,A27)) -> 0 | C27: =IF(A27="",0,SUMIF(ประวัติการขาย!D4:D203,A27,ประวัติการขาย!H4:H203)) -> 0 | D27: =IF(A27="",0,SUMIF(ประวัติการขาย!D4:D203,A27,ประวัติการขาย!G4:G203)) -> 0 | E27: =IF(A27="",0,C27-D27) -> 0 | F27: =IFERROR(E27/C27,0) -> 0 | G27: =B27+ROW()/10000 -> 0.0027 | N27: =E27+ROW()/10000 -> 0.0027
B28: =IF(A28="",0,COUNTIF(ประวัติการขาย!D4:D203,A28)) -> 0 | C28: =IF(A28="",0,SUMIF(ประวัติการขาย!D4:D203,A28,ประวัติการขาย!H4:H203)) -> 0 | D28: =IF(A28="",0,SUMIF(ประวัติการขาย!D4:D203,A28,ประวัติการขาย!G4:G203)) -> 0 | E28: =IF(A28="",0,C28-D28) -> 0 | F28: =IFERROR(E28/C28,0) -> 0 | G28: =B28+ROW()/10000 -> 0.0028 | N28: =E28+ROW()/10000 -> 0.0028
B29: =IF(A29="",0,COUNTIF(ประวัติการขาย!D4:D203,A29)) -> 0 | C29: =IF(A29="",0,SUMIF(ประวัติการขาย!D4:D203,A29,ประวัติการขาย!H4:H203)) -> 0 | D29: =IF(A29="",0,SUMIF(ประวัติการขาย!D4:D203,A29,ประวัติการขาย!G4:G203)) -> 0 | E29: =IF(A29="",0,C29-D29) -> 0 | F29: =IFERROR(E29/C29,0) -> 0 | G29: =B29+ROW()/10000 -> 0.0029 | N29: =E29+ROW()/10000 -> 0.0029
B30: =IF(A30="",0,COUNTIF(ประวัติการขาย!D4:D203,A30)) -> 0 | C30: =IF(A30="",0,SUMIF(ประวัติการขาย!D4:D203,A30,ประวัติการขาย!H4:H203)) -> 0 | D30: =IF(A30="",0,SUMIF(ประวัติการขาย!D4:D203,A30,ประวัติการขาย!G4:G203)) -> 0 | E30: =IF(A30="",0,C30-D30) -> 0 | F30: =IFERROR(E30/C30,0) -> 0 | G30: =B30+ROW()/10000 -> 0.003 | N30: =E30+ROW()/10000 -> 0.003
B31: =IF(A31="",0,COUNTIF(ประวัติการขาย!D4:D203,A31)) -> 0 | C31: =IF(A31="",0,SUMIF(ประวัติการขาย!D4:D203,A31,ประวัติการขาย!H4:H203)) -> 0 | D31: =IF(A31="",0,SUMIF(ประวัติการขาย!D4:D203,A31,ประวัติการขาย!G4:G203)) -> 0 | E31: =IF(A31="",0,C31-D31) -> 0 | F31: =IFERROR(E31/C31,0) -> 0 | G31: =B31+ROW()/10000 -> 0.0031 | N31: =E31+ROW()/10000 -> 0.0031
B32: =IF(A32="",0,COUNTIF(ประวัติการขาย!D4:D203,A32)) -> 0 | C32: =IF(A32="",0,SUMIF(ประวัติการขาย!D4:D203,A32,ประวัติการขาย!H4:H203)) -> 0 | D32: =IF(A32="",0,SUMIF(ประวัติการขาย!D4:D203,A32,ประวัติการขาย!G4:G203)) -> 0 | E32: =IF(A32="",0,C32-D32) -> 0 | F32: =IFERROR(E32/C32,0) -> 0 | G32: =B32+ROW()/10000 -> 0.0032 | N32: =E32+ROW()/10000 -> 0.0032
B33: =IF(A33="",0,COUNTIF(ประวัติการขาย!D4:D203,A33)) -> 0 | C33: =IF(A33="",0,SUMIF(ประวัติการขาย!D4:D203,A33,ประวัติการขาย!H4:H203)) -> 0 | D33: =IF(A33="",0,SUMIF(ประวัติการขาย!D4:D203,A33,ประวัติการขาย!G4:G203)) -> 0 | E33: =IF(A33="",0,C33-D33) -> 0 | F33: =IFERROR(E33/C33,0) -> 0 | G33: =B33+ROW()/10000 -> 0.0033 | N33: =E33+ROW()/10000 -> 0.0033
B34: =IF(A34="",0,COUNTIF(ประวัติการขาย!D4:D203,A34)) -> 0 | C34: =IF(A34="",0,SUMIF(ประวัติการขาย!D4:D203,A34,ประวัติการขาย!H4:H203)) -> 0 | D34: =IF(A34="",0,SUMIF(ประวัติการขาย!D4:D203,A34,ประวัติการขาย!G4:G203)) -> 0 | E34: =IF(A34="",0,C34-D34) -> 0 | F34: =IFERROR(E34/C34,0) -> 0 | G34: =B34+ROW()/10000 -> 0.0034 | N34: =E34+ROW()/10000 -> 0.0034
B35: =IF(A35="",0,COUNTIF(ประวัติการขาย!D4:D203,A35)) -> 0 | C35: =IF(A35="",0,SUMIF(ประวัติการขาย!D4:D203,A35,ประวัติการขาย!H4:H203)) -> 0 | D35: =IF(A35="",0,SUMIF(ประวัติการขาย!D4:D203,A35,ประวัติการขาย!G4:G203)) -> 0 | E35: =IF(A35="",0,C35-D35) -> 0 | F35: =IFERROR(E35/C35,0) -> 0 | G35: =B35+ROW()/10000 -> 0.0035 | N35: =E35+ROW()/10000 -> 0.0035
B36: =IF(A36="",0,COUNTIF(ประวัติการขาย!D4:D203,A36)) -> 0 | C36: =IF(A36="",0,SUMIF(ประวัติการขาย!D4:D203,A36,ประวัติการขาย!H4:H203)) -> 0 | D36: =IF(A36="",0,SUMIF(ประวัติการขาย!D4:D203,A36,ประวัติการขาย!G4:G203)) -> 0 | E36: =IF(A36="",0,C36-D36) -> 0 | F36: =IFERROR(E36/C36,0) -> 0 | G36: =B36+ROW()/10000 -> 0.0036 | N36: =E36+ROW()/10000 -> 0.0036
B37: =IF(A37="",0,COUNTIF(ประวัติการขาย!D4:D203,A37)) -> 0 | C37: =IF(A37="",0,SUMIF(ประวัติการขาย!D4:D203,A37,ประวัติการขาย!H4:H203)) -> 0 | D37: =IF(A37="",0,SUMIF(ประวัติการขาย!D4:D203,A37,ประวัติการขาย!G4:G203)) -> 0 | E37: =IF(A37="",0,C37-D37) -> 0 | F37: =IFERROR(E37/C37,0) -> 0 | G37: =B37+ROW()/10000 -> 0.0037 | N37: =E37+ROW()/10000 -> 0.0037
B38: =IF(A38="",0,COUNTIF(ประวัติการขาย!D4:D203,A38)) -> 0 | C38: =IF(A38="",0,SUMIF(ประวัติการขาย!D4:D203,A38,ประวัติการขาย!H4:H203)) -> 0 | D38: =IF(A38="",0,SUMIF(ประวัติการขาย!D4:D203,A38,ประวัติการขาย!G4:G203)) -> 0 | E38: =IF(A38="",0,C38-D38) -> 0 | F38: =IFERROR(E38/C38,0) -> 0 | G38: =B38+ROW()/10000 -> 0.0038 | N38: =E38+ROW()/10000 -> 0.0038
B39: =IF(A39="",0,COUNTIF(ประวัติการขาย!D4:D203,A39)) -> 0 | C39: =IF(A39="",0,SUMIF(ประวัติการขาย!D4:D203,A39,ประวัติการขาย!H4:H203)) -> 0 | D39: =IF(A39="",0,SUMIF(ประวัติการขาย!D4:D203,A39,ประวัติการขาย!G4:G203)) -> 0 | E39: =IF(A39="",0,C39-D39) -> 0 | F39: =IFERROR(E39/C39,0) -> 0 | G39: =B39+ROW()/10000 -> 0.0039 | N39: =E39+ROW()/10000 -> 0.0039
B40: =IF(A40="",0,COUNTIF(ประวัติการขาย!D4:D203,A40)) -> 0 | C40: =IF(A40="",0,SUMIF(ประวัติการขาย!D4:D203,A40,ประวัติการขาย!H4:H203)) -> 0 | D40: =IF(A40="",0,SUMIF(ประวัติการขาย!D4:D203,A40,ประวัติการขาย!G4:G203)) -> 0 | E40: =IF(A40="",0,C40-D40) -> 0 | F40: =IFERROR(E40/C40,0) -> 0 | G40: =B40+ROW()/10000 -> 0.004 | N40: =E40+ROW()/10000 -> 0.004
...
